[2025-08-27T10:38:44.212+0000] {local_task_job_runner.py:120} INFO - ::group::Pre task execution logs
[2025-08-27T10:38:44.272+0000] {taskinstance.py:2076} INFO - Dependencies all met for dep_context=non-requeueable deps ti=<TaskInstance: s3_upload_pipeline_v1.create_and_upload_file_to_s3 manual__2025-08-27T10:38:39.915529+00:00 [queued]>
[2025-08-27T10:38:44.294+0000] {taskinstance.py:2076} INFO - Dependencies all met for dep_context=requeueable deps ti=<TaskInstance: s3_upload_pipeline_v1.create_and_upload_file_to_s3 manual__2025-08-27T10:38:39.915529+00:00 [queued]>
[2025-08-27T10:38:44.295+0000] {taskinstance.py:2306} INFO - Starting attempt 1 of 1
[2025-08-27T10:38:44.326+0000] {taskinstance.py:2330} INFO - Executing <Task(_PythonDecoratedOperator): create_and_upload_file_to_s3> on 2025-08-27 10:38:39.915529+00:00
[2025-08-27T10:38:44.340+0000] {warnings.py:112} WARNING - /home/***/.local/lib/python3.12/site-packages/***/task/task_runner/standard_task_runner.py:61: DeprecationWarning: This process (pid=32307) is multi-threaded, use of fork() may lead to deadlocks in the child.
  pid = os.fork()

[2025-08-27T10:38:44.347+0000] {standard_task_runner.py:63} INFO - Started process 32309 to run task
[2025-08-27T10:38:44.345+0000] {standard_task_runner.py:90} INFO - Running: ['***', 'tasks', 'run', 's3_upload_pipeline_v1', 'create_and_upload_file_to_s3', 'manual__2025-08-27T10:38:39.915529+00:00', '--job-id', '21', '--raw', '--subdir', 'DAGS_FOLDER/s3_upload_dag.py', '--cfg-path', '/tmp/tmp16ydd1dj']
[2025-08-27T10:38:44.352+0000] {standard_task_runner.py:91} INFO - Job 21: Subtask create_and_upload_file_to_s3
[2025-08-27T10:38:44.474+0000] {task_command.py:426} INFO - Running <TaskInstance: s3_upload_pipeline_v1.create_and_upload_file_to_s3 manual__2025-08-27T10:38:39.915529+00:00 [running]> on host 5ce1f97bdd1f
[2025-08-27T10:38:44.650+0000] {taskinstance.py:2648} INFO - Exporting env vars: AIRFLOW_CTX_DAG_OWNER='***' AIRFLOW_CTX_DAG_ID='s3_upload_pipeline_v1' AIRFLOW_CTX_TASK_ID='create_and_upload_file_to_s3' AIRFLOW_CTX_EXECUTION_DATE='2025-08-27T10:38:39.915529+00:00' AIRFLOW_CTX_TRY_NUMBER='1' AIRFLOW_CTX_DAG_RUN_ID='manual__2025-08-27T10:38:39.915529+00:00'
[2025-08-27T10:38:44.653+0000] {taskinstance.py:430} INFO - ::endgroup::
[2025-08-27T10:38:44.655+0000] {logging_mixin.py:188} INFO - Fajl 'test_iz_***a.txt' kreiran u kontejneru.
[2025-08-27T10:38:44.970+0000] {logging_mixin.py:188} INFO - Uploadujem fajl u bucket 'milos-de-portfolio-bucket-2025'...
[2025-08-27T10:38:44.979+0000] {taskinstance.py:441} INFO - ::group::Post task execution logs
[2025-08-27T10:38:44.980+0000] {taskinstance.py:2905} ERROR - Task failed with exception
Traceback (most recent call last):
  File "/home/airflow/.local/lib/python3.12/site-packages/airflow/models/taskinstance.py", line 465, in _execute_task
    result = _execute_callable(context=context, **execute_callable_kwargs)
             ^^^^^^^^^^^^^^^^^^^^^^^^^^^^^^^^^^^^^^^^^^^^^^^^^^^^^^^^^^^^^
  File "/home/airflow/.local/lib/python3.12/site-packages/airflow/models/taskinstance.py", line 432, in _execute_callable
    return execute_callable(context=context, **execute_callable_kwargs)
           ^^^^^^^^^^^^^^^^^^^^^^^^^^^^^^^^^^^^^^^^^^^^^^^^^^^^^^^^^^^^
  File "/home/airflow/.local/lib/python3.12/site-packages/airflow/models/baseoperator.py", line 401, in wrapper
    return func(self, *args, **kwargs)
           ^^^^^^^^^^^^^^^^^^^^^^^^^^^
  File "/home/airflow/.local/lib/python3.12/site-packages/airflow/decorators/base.py", line 265, in execute
    return_value = super().execute(context)
                   ^^^^^^^^^^^^^^^^^^^^^^^^
  File "/home/airflow/.local/lib/python3.12/site-packages/airflow/models/baseoperator.py", line 401, in wrapper
    return func(self, *args, **kwargs)
           ^^^^^^^^^^^^^^^^^^^^^^^^^^^
  File "/home/airflow/.local/lib/python3.12/site-packages/airflow/operators/python.py", line 235, in execute
    return_value = self.execute_callable()
                   ^^^^^^^^^^^^^^^^^^^^^^^
  File "/home/airflow/.local/lib/python3.12/site-packages/airflow/operators/python.py", line 252, in execute_callable
    return self.python_callable(*self.op_args, **self.op_kwargs)
           ^^^^^^^^^^^^^^^^^^^^^^^^^^^^^^^^^^^^^^^^^^^^^^^^^^^^^
  File "/opt/airflow/dags/s3_upload_dag.py", line 39, in create_and_upload_file_to_s3
    s3_client.upload_file(f"/tmp/{file_name}", BUCKET_NAME, file_name)
  File "/home/airflow/.local/lib/python3.12/site-packages/boto3/s3/inject.py", line 145, in upload_file
    return transfer.upload_file(
           ^^^^^^^^^^^^^^^^^^^^^
  File "/home/airflow/.local/lib/python3.12/site-packages/boto3/s3/transfer.py", line 371, in upload_file
    future.result()
  File "/home/airflow/.local/lib/python3.12/site-packages/s3transfer/futures.py", line 103, in result
    return self._coordinator.result()
           ^^^^^^^^^^^^^^^^^^^^^^^^^^
  File "/home/airflow/.local/lib/python3.12/site-packages/s3transfer/futures.py", line 266, in result
    raise self._exception
  File "/home/airflow/.local/lib/python3.12/site-packages/s3transfer/tasks.py", line 139, in __call__
    return self._execute_main(kwargs)
           ^^^^^^^^^^^^^^^^^^^^^^^^^^
  File "/home/airflow/.local/lib/python3.12/site-packages/s3transfer/tasks.py", line 162, in _execute_main
    return_value = self._main(**kwargs)
                   ^^^^^^^^^^^^^^^^^^^^
  File "/home/airflow/.local/lib/python3.12/site-packages/s3transfer/upload.py", line 764, in _main
    client.put_object(Bucket=bucket, Key=key, Body=body, **extra_args)
  File "/home/airflow/.local/lib/python3.12/site-packages/botocore/client.py", line 565, in _api_call
    return self._make_api_call(operation_name, kwargs)
           ^^^^^^^^^^^^^^^^^^^^^^^^^^^^^^^^^^^^^^^^^^^
  File "/home/airflow/.local/lib/python3.12/site-packages/botocore/client.py", line 1001, in _make_api_call
    http, parsed_response = self._make_request(
                            ^^^^^^^^^^^^^^^^^^^
  File "/home/airflow/.local/lib/python3.12/site-packages/botocore/client.py", line 1027, in _make_request
    return self._endpoint.make_request(operation_model, request_dict)
           ^^^^^^^^^^^^^^^^^^^^^^^^^^^^^^^^^^^^^^^^^^^^^^^^^^^^^^^^^^
  File "/home/airflow/.local/lib/python3.12/site-packages/botocore/endpoint.py", line 119, in make_request
    return self._send_request(request_dict, operation_model)
           ^^^^^^^^^^^^^^^^^^^^^^^^^^^^^^^^^^^^^^^^^^^^^^^^^
  File "/home/airflow/.local/lib/python3.12/site-packages/botocore/endpoint.py", line 198, in _send_request
    request = self.create_request(request_dict, operation_model)
              ^^^^^^^^^^^^^^^^^^^^^^^^^^^^^^^^^^^^^^^^^^^^^^^^^^
  File "/home/airflow/.local/lib/python3.12/site-packages/botocore/endpoint.py", line 134, in create_request
    self._event_emitter.emit(
  File "/home/airflow/.local/lib/python3.12/site-packages/botocore/hooks.py", line 412, in emit
    return self._emitter.emit(aliased_event_name, **kwargs)
           ^^^^^^^^^^^^^^^^^^^^^^^^^^^^^^^^^^^^^^^^^^^^^^^^
  File "/home/airflow/.local/lib/python3.12/site-packages/botocore/hooks.py", line 256, in emit
    return self._emit(event_name, kwargs)
           ^^^^^^^^^^^^^^^^^^^^^^^^^^^^^^
  File "/home/airflow/.local/lib/python3.12/site-packages/botocore/hooks.py", line 239, in _emit
    response = handler(**kwargs)
               ^^^^^^^^^^^^^^^^^
  File "/home/airflow/.local/lib/python3.12/site-packages/botocore/signers.py", line 105, in handler
    return self.sign(operation_name, request)
           ^^^^^^^^^^^^^^^^^^^^^^^^^^^^^^^^^^
  File "/home/airflow/.local/lib/python3.12/site-packages/botocore/signers.py", line 199, in sign
    auth.add_auth(request)
  File "/home/airflow/.local/lib/python3.12/site-packages/botocore/auth.py", line 418, in add_auth
    raise NoCredentialsError()
botocore.exceptions.NoCredentialsError: Unable to locate credentials
[2025-08-27T10:38:45.009+0000] {taskinstance.py:1206} INFO - Marking task as FAILED. dag_id=s3_upload_pipeline_v1, task_id=create_and_upload_file_to_s3, run_id=manual__2025-08-27T10:38:39.915529+00:00, execution_date=20250827T103839, start_date=20250827T103844, end_date=20250827T103845
[2025-08-27T10:38:45.034+0000] {standard_task_runner.py:110} ERROR - Failed to execute job 21 for task create_and_upload_file_to_s3 (Unable to locate credentials; 32309)
[2025-08-27T10:38:45.086+0000] {local_task_job_runner.py:240} INFO - Task exited with return code 1
[2025-08-27T10:38:45.112+0000] {taskinstance.py:3503} INFO - 0 downstream tasks scheduled from follow-on schedule check
[2025-08-27T10:38:45.118+0000] {local_task_job_runner.py:222} INFO - ::endgroup::
